<sdf version='1.7'>
  <world name='default'>
    <model name='ground_plane'>
      <static>1</static>
      <link name='link'>
        <collision name='collision'>
          <geometry>
            <plane>
              <normal>0 0 1</normal>
              <size>100 100</size>
            </plane>
          </geometry>
          <surface>
            <contact>
              <collide_bitmask>65535</collide_bitmask>
              <ode/>
            </contact>
            <friction>
              <ode>
                <mu>100</mu>
                <mu2>50</mu2>
              </ode>
              <torsional>
                <ode/>
              </torsional>
            </friction>
            <bounce/>
          </surface>
          <max_contacts>10</max_contacts>
        </collision>
        <visual name='visual'>
          <cast_shadows>0</cast_shadows>
          <geometry>
            <plane>
              <normal>0 0 1</normal>
              <size>100 100</size>
            </plane>
          </geometry>
          <material>
            <script>
              <uri>file://media/materials/scripts/gazebo.material</uri>
              <name>Gazebo/Grey</name>
            </script>
          </material>
        </visual>
        <self_collide>0</self_collide>
        <enable_wind>0</enable_wind>
        <kinematic>0</kinematic>
      </link>
    </model>
    <light name='sun' type='directional'>
      <cast_shadows>1</cast_shadows>
      <pose>0 0 10 0 -0 0</pose>
      <diffuse>0.8 0.8 0.8 1</diffuse>
      <specular>0.2 0.2 0.2 1</specular>
      <attenuation>
        <range>1000</range>
        <constant>0.9</constant>
        <linear>0.01</linear>
        <quadratic>0.001</quadratic>
      </attenuation>
      <direction>-0.5 0.1 -0.9</direction>
      <spot>
        <inner_angle>0</inner_angle>
        <outer_angle>0</outer_angle>
        <falloff>0</falloff>
      </spot>
    </light>
    <gravity>0 0 -9.8</gravity>
    <magnetic_field>6e-06 2.3e-05 -4.2e-05</magnetic_field>
    <atmosphere type='adiabatic'/>
    <physics type='ode'>
      <max_step_size>0.001</max_step_size>
      <real_time_factor>1</real_time_factor>
      <real_time_update_rate>1000</real_time_update_rate>
    </physics>
    <scene>
      <ambient>0.4 0.4 0.4 1</ambient>
      <background>0.7 0.7 0.7 1</background>
      <shadows>1</shadows>
    </scene>
    <audio>
      <device>default</device>
    </audio>
    <wind/>
    <spherical_coordinates>
      <surface_model>EARTH_WGS84</surface_model>
      <latitude_deg>0</latitude_deg>
      <longitude_deg>0</longitude_deg>
      <elevation>0</elevation>
      <heading_deg>0</heading_deg>
    </spherical_coordinates>
    <model name='kratos'>
      <link name='base_link'>
        <inertial>
          <pose>0 0 0 0 -0 0</pose>
          <mass>20</mass>
          <inertia>
            <ixx>1</ixx>
            <ixy>0</ixy>
            <ixz>0</ixz>
            <iyy>1</iyy>
            <iyz>0</iyz>
            <izz>1</izz>
          </inertia>
        </inertial>
        <collision name='base_link_collision'>
          <pose>0 0 0 0 -0 0</pose>
          <geometry>
            <mesh>
              <scale>0.001 0.001 0.001</scale>
              <uri>model://kratos_description/meshes/body.stl</uri>
            </mesh>
          </geometry>
          <surface>
            <contact>
              <ode>
                <kp>1e+06</kp>
                <kd>1</kd>
              </ode>
            </contact>
            <friction>
              <ode>
                <mu>0.5</mu>
                <mu2>0.5</mu2>
              </ode>
              <torsional>
                <ode/>
              </torsional>
            </friction>
            <bounce/>
          </surface>
          <max_contacts>10</max_contacts>
        </collision>
        <collision name='base_link_fixed_joint_lump__zed_camera_center_collision_1'>
          <pose>0.24 0 0.015 0 -0 0</pose>
          <geometry>
            <mesh>
              <scale>1 1 1</scale>
              <uri>file:///opt/ros/humble/share/zed_msgs/meshes/zed2i.stl</uri>
            </mesh>
          </geometry>
          <max_contacts>10</max_contacts>
          <surface>
            <contact>
              <ode/>
            </contact>
            <bounce/>
            <friction>
              <torsional>
                <ode/>
              </torsional>
              <ode/>
            </friction>
          </surface>
        </collision>
        <visual name='base_link_visual'>
          <pose>0 0 0 0 0 -1.5708</pose>
          <geometry>
            <mesh>
              <scale>0.001 0.001 0.001</scale>
              <uri>model://kratos_description/meshes/body.stl</uri>
            </mesh>
          </geometry>
          <material>
            <script>
              <name>Gazebo/Blue</name>
              <uri>file://media/materials/scripts/gazebo.material</uri>
            </script>
          </material>
        </visual>
        <visual name='base_link_fixed_joint_lump__zed_camera_center_visual_1'>
          <pose>0.24 0 0.015 0 -0 0</pose>
          <geometry>
            <mesh>
              <scale>1 1 1</scale>
              <uri>file:///opt/ros/humble/share/zed_msgs/meshes/zed2i.stl</uri>
            </mesh>
          </geometry>
        </visual>
        <sensor name='gps_sensor' type='gps'>
          <always_on>1</always_on>
          <update_rate>5</update_rate>
          <plugin name='gps_controller' filename='libgazebo_ros_gps_sensor.so'>
            <ros>
              <namespace>/mavros/global_position</namespace>
              <remapping>~/out:=global</remapping>
            </ros>
            <output_type>sensor_msgs/NavSatFix</output_type>
          </plugin>
          <gps/>
        </sensor>
        <sensor name='zed_camera' type='depth'>
          <visualize>0</visualize>
          <update_rate>10</update_rate>
          <camera name='zed'>
            <horizontal_fov>1.91986</horizontal_fov>
            <image>
              <width>640</width>
              <height>480</height>
              <format>R8G8B8</format>
            </image>
            <clip>
              <near>0.3</near>
              <far>20</far>
            </clip>
            <noise>
              <type>gaussian</type>
              <mean>0</mean>
              <stddev>0.007</stddev>
            </noise>
          </camera>
          <plugin name='camera_controller' filename='libgazebo_ros_camera.so'>
            <ros>
              <namespace>zed</namespace>
              <remapping>zed_camera/image_raw:=zed_node/left/image_rect_color</remapping>
              <remapping>zed_camera/camera_info:=zed_node/left/camera_info</remapping>
              <remapping>zed_camera/depth/image_raw:=zed_node/depth/depth_registered</remapping>
              <remapping>zed_camera/points:=zed_node/point_cloud/cloud_registered</remapping>
              <remapping>zed_camera/depth/camera_info:=zed_node/depth/camera_info</remapping>
            </ros>
            <frame_name>zed_left_camera_frame_optical</frame_name>
            <min_depth>0.3</min_depth>
            <max_depth>20.0</max_depth>
            <ros>
              <qos>
                <topic name='zed_node/rgb/image_rect_color'>
                  <publisher>
                    <reliability>best_effort</reliability>
                    <durability>volatile</durability>
                    <deadline>
                      <sec>0</sec>
                      <nsec>100000000</nsec>
                    </deadline>
                    <lifespan>
                      <sec>1</sec>
                      <nsec>0</nsec>
                    </lifespan>
                  </publisher>
                </topic>
                <topic name='zed_node/depth/depth_registered'>
                  <publisher>
                    <reliability>best_effort</reliability>
                    <durability>volatile</durability>
                    <deadline>
                      <sec>0</sec>
                      <nsec>100000000</nsec>
                    </deadline>
                    <lifespan>
                      <sec>1</sec>
                      <nsec>0</nsec>
                    </lifespan>
                  </publisher>
                </topic>
              </qos>
            </ros>
          </plugin>
          <pose>0.24 0.06 0.015 0 -0 0</pose>
        </sensor>
        <sensor name='zed_imu' type='imu'>
          <always_on>1</always_on>
          <update_rate>100</update_rate>
          <visualize>1</visualize>
          <imu>
            <angular_velocity>
              <x>
                <noise type='gaussian'>
                  <mean>0</mean>
                  <stddev>0.0002</stddev>
                </noise>
              </x>
              <y>
                <noise type='gaussian'>
                  <mean>0</mean>
                  <stddev>0.0002</stddev>
                </noise>
              </y>
              <z>
                <noise type='gaussian'>
                  <mean>0</mean>
                  <stddev>0.0002</stddev>
                </noise>
              </z>
            </angular_velocity>
            <linear_acceleration>
              <x>
                <noise type='gaussian'>
                  <mean>0</mean>
                  <stddev>0.017</stddev>
                </noise>
              </x>
              <y>
                <noise type='gaussian'>
                  <mean>0</mean>
                  <stddev>0.017</stddev>
                </noise>
              </y>
              <z>
                <noise type='gaussian'>
                  <mean>0</mean>
                  <stddev>0.017</stddev>
                </noise>
              </z>
            </linear_acceleration>
          </imu>
          <plugin name='imu_plugin' filename='libgazebo_ros_imu_sensor.so'>
            <ros>
              <namespace>zed</namespace>
              <remapping>~/out:=zed_node/imu/data</remapping>
            </ros>
            <initial_orientation_as_reference>0</initial_orientation_as_reference>
          </plugin>
          <pose>0.24 0.06 0.015 0 -0 0</pose>
        </sensor>
        <self_collide>0</self_collide>
        <enable_wind>0</enable_wind>
        <kinematic>0</kinematic>
      </link>
      <joint name='left_wheel_front_joint' type='revolute'>
        <pose relative_to='base_link'>0.4 0.5 -0.5 0 -0 0</pose>
        <parent>base_link</parent>
        <child>left_wheel_front</child>
        <axis>
          <xyz>0 1 0</xyz>
          <limit>
            <lower>-1000</lower>
            <upper>1000</upper>
            <effort>5</effort>
            <velocity>10</velocity>
          </limit>
          <dynamics>
            <spring_reference>0</spring_reference>
            <spring_stiffness>0</spring_stiffness>
          </dynamics>
        </axis>
      </joint>
      <link name='left_wheel_front'>
        <pose relative_to='left_wheel_front_joint'>0 0 0 0 -0 0</pose>
        <inertial>
          <pose>0 0 0 0 -0 0</pose>
          <mass>2</mass>
          <inertia>
            <ixx>0.01</ixx>
            <ixy>0</ixy>
            <ixz>0</ixz>
            <iyy>0.01</iyy>
            <iyz>0</iyz>
            <izz>0.01</izz>
          </inertia>
        </inertial>
        <collision name='left_wheel_front_collision'>
          <pose>0 0 0 1.5708 -0 0</pose>
          <geometry>
            <mesh>
              <scale>0.001 0.001 0.001</scale>
              <uri>model://kratos_description/meshes/wheel.stl</uri>
            </mesh>
          </geometry>
          <surface>
            <contact>
              <ode>
                <kp>1e+06</kp>
                <kd>1</kd>
              </ode>
            </contact>
            <friction>
              <ode>
                <mu>0</mu>
                <mu2>0</mu2>
              </ode>
              <torsional>
                <ode/>
              </torsional>
            </friction>
            <bounce/>
          </surface>
          <max_contacts>10</max_contacts>
        </collision>
        <visual name='left_wheel_front_visual'>
          <pose>0 0 0 1.5708 -0 0</pose>
          <geometry>
            <mesh>
              <scale>0.001 0.001 0.001</scale>
              <uri>model://kratos_description/meshes/wheel.stl</uri>
            </mesh>
          </geometry>
          <material>
            <script>
              <name>Gazebo/Black</name>
              <uri>file://media/materials/scripts/gazebo.material</uri>
            </script>
          </material>
        </visual>
        <self_collide>0</self_collide>
        <enable_wind>0</enable_wind>
        <kinematic>0</kinematic>
      </link>
      <joint name='left_wheel_middle_joint' type='revolute'>
        <pose relative_to='base_link'>0 0.5 -0.5 0 -0 0</pose>
        <parent>base_link</parent>
        <child>left_wheel_middle</child>
        <axis>
          <xyz>0 1 0</xyz>
          <limit>
            <lower>-1000</lower>
            <upper>1000</upper>
            <effort>5</effort>
            <velocity>10</velocity>
          </limit>
          <dynamics>
            <spring_reference>0</spring_reference>
            <spring_stiffness>0</spring_stiffness>
          </dynamics>
        </axis>
      </joint>
      <link name='left_wheel_middle'>
        <pose relative_to='left_wheel_middle_joint'>0 0 0 0 -0 0</pose>
        <inertial>
          <pose>0 0 0 0 -0 0</pose>
          <mass>2</mass>
          <inertia>
            <ixx>0.01</ixx>
            <ixy>0</ixy>
            <ixz>0</ixz>
            <iyy>0.01</iyy>
            <iyz>0</iyz>
            <izz>0.01</izz>
          </inertia>
        </inertial>
        <collision name='left_wheel_middle_collision'>
          <pose>0 0 0 1.5708 -0 0</pose>
          <geometry>
            <mesh>
              <scale>0.001 0.001 0.001</scale>
              <uri>model://kratos_description/meshes/wheel.stl</uri>
            </mesh>
          </geometry>
          <surface>
            <contact>
              <ode>
                <kp>1e+06</kp>
                <kd>1</kd>
              </ode>
            </contact>
            <friction>
              <ode>
                <mu>1</mu>
                <mu2>1</mu2>
              </ode>
              <torsional>
                <ode/>
              </torsional>
            </friction>
            <bounce/>
          </surface>
          <max_contacts>10</max_contacts>
        </collision>
        <visual name='left_wheel_middle_visual'>
          <pose>0 0 0 1.5708 -0 0</pose>
          <geometry>
            <mesh>
              <scale>0.001 0.001 0.001</scale>
              <uri>model://kratos_description/meshes/wheel.stl</uri>
            </mesh>
          </geometry>
          <material>
            <script>
              <name>Gazebo/Black</name>
              <uri>file://media/materials/scripts/gazebo.material</uri>
            </script>
          </material>
        </visual>
        <self_collide>0</self_collide>
        <enable_wind>0</enable_wind>
        <kinematic>0</kinematic>
      </link>
      <joint name='left_wheel_rear_joint' type='revolute'>
        <pose relative_to='base_link'>-0.4 0.5 -0.5 0 -0 0</pose>
        <parent>base_link</parent>
        <child>left_wheel_rear</child>
        <axis>
          <xyz>0 1 0</xyz>
          <limit>
            <lower>-1000</lower>
            <upper>1000</upper>
            <effort>5</effort>
            <velocity>10</velocity>
          </limit>
          <dynamics>
            <spring_reference>0</spring_reference>
            <spring_stiffness>0</spring_stiffness>
          </dynamics>
        </axis>
      </joint>
      <link name='left_wheel_rear'>
        <pose relative_to='left_wheel_rear_joint'>0 0 0 0 -0 0</pose>
        <inertial>
          <pose>0 0 0 0 -0 0</pose>
          <mass>2</mass>
          <inertia>
            <ixx>0.01</ixx>
            <ixy>0</ixy>
            <ixz>0</ixz>
            <iyy>0.01</iyy>
            <iyz>0</iyz>
            <izz>0.01</izz>
          </inertia>
        </inertial>
        <collision name='left_wheel_rear_collision'>
          <pose>0 0 0 1.5708 -0 0</pose>
          <geometry>
            <mesh>
              <scale>0.001 0.001 0.001</scale>
              <uri>model://kratos_description/meshes/wheel.stl</uri>
            </mesh>
          </geometry>
          <surface>
            <contact>
              <ode>
                <kp>1e+06</kp>
                <kd>1</kd>
              </ode>
            </contact>
            <friction>
              <ode>
                <mu>0</mu>
                <mu2>0</mu2>
              </ode>
              <torsional>
                <ode/>
              </torsional>
            </friction>
            <bounce/>
          </surface>
          <max_contacts>10</max_contacts>
        </collision>
        <visual name='left_wheel_rear_visual'>
          <pose>0 0 0 1.5708 -0 0</pose>
          <geometry>
            <mesh>
              <scale>0.001 0.001 0.001</scale>
              <uri>model://kratos_description/meshes/wheel.stl</uri>
            </mesh>
          </geometry>
          <material>
            <script>
              <name>Gazebo/Black</name>
              <uri>file://media/materials/scripts/gazebo.material</uri>
            </script>
          </material>
        </visual>
        <self_collide>0</self_collide>
        <enable_wind>0</enable_wind>
        <kinematic>0</kinematic>
      </link>
      <joint name='right_wheel_front_joint' type='revolute'>
        <pose relative_to='base_link'>0.4 -0.5 -0.5 0 -0 0</pose>
        <parent>base_link</parent>
        <child>right_wheel_front</child>
        <axis>
          <xyz>0 1 0</xyz>
          <limit>
            <lower>-1000</lower>
            <upper>1000</upper>
            <effort>5</effort>
            <velocity>10</velocity>
          </limit>
          <dynamics>
            <spring_reference>0</spring_reference>
            <spring_stiffness>0</spring_stiffness>
          </dynamics>
        </axis>
      </joint>
      <link name='right_wheel_front'>
        <pose relative_to='right_wheel_front_joint'>0 0 0 0 -0 0</pose>
        <inertial>
          <pose>0 0 0 0 -0 0</pose>
          <mass>2</mass>
          <inertia>
            <ixx>0.01</ixx>
            <ixy>0</ixy>
            <ixz>0</ixz>
            <iyy>0.01</iyy>
            <iyz>0</iyz>
            <izz>0.01</izz>
          </inertia>
        </inertial>
        <collision name='right_wheel_front_collision'>
          <pose>0 0 0 -1.5708 0 0</pose>
          <geometry>
            <mesh>
              <scale>0.001 0.001 0.001</scale>
              <uri>model://kratos_description/meshes/wheel.stl</uri>
            </mesh>
          </geometry>
          <surface>
            <contact>
              <ode>
                <kp>1e+06</kp>
                <kd>1</kd>
              </ode>
            </contact>
            <friction>
              <ode>
                <mu>0</mu>
                <mu2>0</mu2>
              </ode>
              <torsional>
                <ode/>
              </torsional>
            </friction>
            <bounce/>
          </surface>
          <max_contacts>10</max_contacts>
        </collision>
        <visual name='right_wheel_front_visual'>
          <pose>0 0 0 -1.5708 0 0</pose>
          <geometry>
            <mesh>
              <scale>0.001 0.001 0.001</scale>
              <uri>model://kratos_description/meshes/wheel.stl</uri>
            </mesh>
          </geometry>
          <material>
            <script>
              <name>Gazebo/Black</name>
              <uri>file://media/materials/scripts/gazebo.material</uri>
            </script>
          </material>
        </visual>
        <self_collide>0</self_collide>
        <enable_wind>0</enable_wind>
        <kinematic>0</kinematic>
      </link>
      <joint name='right_wheel_middle_joint' type='revolute'>
        <pose relative_to='base_link'>0 -0.5 -0.5 0 -0 0</pose>
        <parent>base_link</parent>
        <child>right_wheel_middle</child>
        <axis>
          <xyz>0 1 0</xyz>
          <limit>
            <lower>-1000</lower>
            <upper>1000</upper>
            <effort>5</effort>
            <velocity>10</velocity>
          </limit>
          <dynamics>
            <spring_reference>0</spring_reference>
            <spring_stiffness>0</spring_stiffness>
          </dynamics>
        </axis>
      </joint>
      <link name='right_wheel_middle'>
        <pose relative_to='right_wheel_middle_joint'>0 0 0 0 -0 0</pose>
        <inertial>
          <pose>0 0 0 0 -0 0</pose>
          <mass>2</mass>
          <inertia>
            <ixx>0.01</ixx>
            <ixy>0</ixy>
            <ixz>0</ixz>
            <iyy>0.01</iyy>
            <iyz>0</iyz>
            <izz>0.01</izz>
          </inertia>
        </inertial>
        <collision name='right_wheel_middle_collision'>
          <pose>0 0 0 -1.5708 0 0</pose>
          <geometry>
            <mesh>
              <scale>0.001 0.001 0.001</scale>
              <uri>model://kratos_description/meshes/wheel.stl</uri>
            </mesh>
          </geometry>
          <surface>
            <contact>
              <ode>
                <kp>1e+06</kp>
                <kd>1</kd>
              </ode>
            </contact>
            <friction>
              <ode>
                <mu>1</mu>
                <mu2>1</mu2>
              </ode>
              <torsional>
                <ode/>
              </torsional>
            </friction>
            <bounce/>
          </surface>
          <max_contacts>10</max_contacts>
        </collision>
        <visual name='right_wheel_middle_visual'>
          <pose>0 0 0 -1.5708 0 0</pose>
          <geometry>
            <mesh>
              <scale>0.001 0.001 0.001</scale>
              <uri>model://kratos_description/meshes/wheel.stl</uri>
            </mesh>
          </geometry>
          <material>
            <script>
              <name>Gazebo/Black</name>
              <uri>file://media/materials/scripts/gazebo.material</uri>
            </script>
          </material>
        </visual>
        <self_collide>0</self_collide>
        <enable_wind>0</enable_wind>
        <kinematic>0</kinematic>
      </link>
      <joint name='right_wheel_rear_joint' type='revolute'>
        <pose relative_to='base_link'>-0.4 -0.5 -0.5 0 -0 0</pose>
        <parent>base_link</parent>
        <child>right_wheel_rear</child>
        <axis>
          <xyz>0 1 0</xyz>
          <limit>
            <lower>-1000</lower>
            <upper>1000</upper>
            <effort>5</effort>
            <velocity>10</velocity>
          </limit>
          <dynamics>
            <spring_reference>0</spring_reference>
            <spring_stiffness>0</spring_stiffness>
          </dynamics>
        </axis>
      </joint>
      <link name='right_wheel_rear'>
        <pose relative_to='right_wheel_rear_joint'>0 0 0 0 -0 0</pose>
        <inertial>
          <pose>0 0 0 0 -0 0</pose>
          <mass>2</mass>
          <inertia>
            <ixx>0.01</ixx>
            <ixy>0</ixy>
            <ixz>0</ixz>
            <iyy>0.01</iyy>
            <iyz>0</iyz>
            <izz>0.01</izz>
          </inertia>
        </inertial>
        <collision name='right_wheel_rear_collision'>
          <pose>0 0 0 -1.5708 0 0</pose>
          <geometry>
            <mesh>
              <scale>0.001 0.001 0.001</scale>
              <uri>model://kratos_description/meshes/wheel.stl</uri>
            </mesh>
          </geometry>
          <surface>
            <contact>
              <ode>
                <kp>1e+06</kp>
                <kd>1</kd>
              </ode>
            </contact>
            <friction>
              <ode>
                <mu>0</mu>
                <mu2>0</mu2>
              </ode>
              <torsional>
                <ode/>
              </torsional>
            </friction>
            <bounce/>
          </surface>
          <max_contacts>10</max_contacts>
        </collision>
        <visual name='right_wheel_rear_visual'>
          <pose>0 0 0 -1.5708 0 0</pose>
          <geometry>
            <mesh>
              <scale>0.001 0.001 0.001</scale>
              <uri>model://kratos_description/meshes/wheel.stl</uri>
            </mesh>
          </geometry>
          <material>
            <script>
              <name>Gazebo/Black</name>
              <uri>file://media/materials/scripts/gazebo.material</uri>
            </script>
          </material>
        </visual>
        <self_collide>0</self_collide>
        <enable_wind>0</enable_wind>
        <kinematic>0</kinematic>
      </link>
      <plugin name='differential_drive_controller' filename='libgazebo_ros_diff_drive.so'>
        <ros>
          <namespace>/</namespace>
          <remapping>cmd_vel:=cmd_vel_true</remapping>
          <remapping>odom:=odom</remapping>
        </ros>
        <update_rate>50</update_rate>
        <left_joint>left_wheel_middle_joint</left_joint>
        <right_joint>right_wheel_middle_joint</right_joint>
        <wheel_separation>0.5</wheel_separation>
        <wheel_diameter>0.2</wheel_diameter>
        <max_wheel_torque>20</max_wheel_torque>
        <max_wheel_acceleration>1.0</max_wheel_acceleration>
        <publish_odom>1</publish_odom>
        <publish_odom_tf>1</publish_odom_tf>
        <publish_wheel_tf>1</publish_wheel_tf>
        <odometry_frame>odom</odometry_frame>
        <robot_base_frame>base_link</robot_base_frame>
      </plugin>
      <static>0</static>
      <plugin name='gazebo_ros_joint_state_publisher' filename='libgazebo_ros_joint_state_publisher.so'>
        <ros>
          <namespace>/</namespace>
        </ros>
        <update_rate>50</update_rate>
        <joint_name>left_wheel_front_joint</joint_name>
        <joint_name>left_wheel_middle_joint</joint_name>
        <joint_name>left_wheel_rear_joint</joint_name>
        <joint_name>right_wheel_front_joint</joint_name>
        <joint_name>right_wheel_middle_joint</joint_name>
        <joint_name>right_wheel_rear_joint</joint_name>
      </plugin>
      <pose>0 0 0.2 0 -0 0</pose>
    </model>
    <model name='cone_2_clone'>
      <link name='link'>
        <collision name='collision'>
          <geometry>
            <mesh>
              <scale>5 5 5</scale>
              <uri>model://construction_cone_blue/meshes/construction_cone.dae</uri>
            </mesh>
          </geometry>
          <max_contacts>10</max_contacts>
          <surface>
            <contact>
              <ode/>
            </contact>
            <bounce/>
            <friction>
              <torsional>
                <ode/>
              </torsional>
              <ode/>
            </friction>
          </surface>
        </collision>
        <visual name='visual'>
          <geometry>
            <mesh>
              <scale>5 5 5</scale>
              <uri>model://construction_cone_blue/meshes/construction_cone.dae</uri>
            </mesh>
          </geometry>
          <material>
            <ambient>0.15 0.25 0.9 1</ambient>
            <diffuse>0.15 0.25 0.9 1</diffuse>
          </material>
        </visual>
        <self_collide>0</self_collide>
        <inertial>
          <pose>0 0 0 0 -0 0</pose>
          <inertia>
            <ixx>1</ixx>
            <ixy>0</ixy>
            <ixz>0</ixz>
            <iyy>1</iyy>
            <iyz>0</iyz>
            <izz>1</izz>
          </inertia>
          <mass>1</mass>
        </inertial>
        <enable_wind>0</enable_wind>
        <kinematic>0</kinematic>
      </link>
      <pose>7 -1.56454 0 0 -0 0</pose>
    </model>
    <model name='cone_2_clone_clone'>
      <link name='link'>
        <collision name='collision'>
          <geometry>
            <mesh>
              <scale>5 5 5</scale>
              <uri>model://construction_cone_blue/meshes/construction_cone.dae</uri>
            </mesh>
          </geometry>
          <max_contacts>10</max_contacts>
          <surface>
            <contact>
              <ode/>
            </contact>
            <bounce/>
            <friction>
              <torsional>
                <ode/>
              </torsional>
              <ode/>
            </friction>
          </surface>
        </collision>
        <visual name='visual'>
          <geometry>
            <mesh>
              <scale>5 5 5</scale>
              <uri>model://construction_cone_blue/meshes/construction_cone.dae</uri>
            </mesh>
          </geometry>
          <material>
            <ambient>0.15 0.25 0.9 1</ambient>
            <diffuse>0.15 0.25 0.9 1</diffuse>
          </material>
        </visual>
        <self_collide>0</self_collide>
        <inertial>
          <pose>0 0 0 0 -0 0</pose>
          <inertia>
            <ixx>1</ixx>
            <ixy>0</ixy>
            <ixz>0</ixz>
            <iyy>1</iyy>
            <iyz>0</iyz>
            <izz>1</izz>
          </inertia>
          <mass>1</mass>
        </inertial>
        <enable_wind>0</enable_wind>
        <kinematic>0</kinematic>
      </link>
      <pose>-3 6 0 0 -0 0</pose>
    </model>
    <model name='Construction Cone'>
      <link name='link'>
        <collision name='collision'>
          <geometry>
            <mesh>
              <scale>5 5 5</scale>
              <uri>model://construction_cone_red/meshes/construction_cone.dae</uri>
            </mesh>
          </geometry>
          <max_contacts>10</max_contacts>
          <surface>
            <contact>
              <ode/>
            </contact>
            <bounce/>
            <friction>
              <torsional>
                <ode/>
              </torsional>
              <ode/>
            </friction>
          </surface>
        </collision>
        <visual name='visual'>
          <geometry>
            <mesh>
              <scale>5 5 5</scale>
              <uri>model://construction_cone_red/meshes/construction_cone.dae</uri>
            </mesh>
          </geometry>
          <material>
            <ambient>0.9 0.15 0.15 1</ambient>
            <diffuse>0.9 0.15 0.15 1</diffuse>
          </material>
        </visual>
        <self_collide>0</self_collide>
        <inertial>
          <pose>0 0 0 0 -0 0</pose>
          <inertia>
            <ixx>1</ixx>
            <ixy>0</ixy>
            <ixz>0</ixz>
            <iyy>1</iyy>
            <iyz>0</iyz>
            <izz>1</izz>
          </inertia>
          <mass>1</mass>
        </inertial>
        <enable_wind>0</enable_wind>
        <kinematic>0</kinematic>
      </link>
      <pose>6 7 0 0 -0 0</pose>
    </model>
    <model name='Construction Cone_0'>
      <link name='link'>
        <collision name='collision'>
          <geometry>
            <mesh>
              <scale>5 5 5</scale>
              <uri>model://construction_cone_red/meshes/construction_cone.dae</uri>
            </mesh>
          </geometry>
          <max_contacts>10</max_contacts>
          <surface>
            <contact>
              <ode/>
            </contact>
            <bounce/>
            <friction>
              <torsional>
                <ode/>
              </torsional>
              <ode/>
            </friction>
          </surface>
        </collision>
        <visual name='visual'>
          <geometry>
            <mesh>
              <scale>5 5 5</scale>
              <uri>model://construction_cone_red/meshes/construction_cone.dae</uri>
            </mesh>
          </geometry>
          <material>
            <ambient>0.9 0.15 0.15 1</ambient>
            <diffuse>0.9 0.15 0.15 1</diffuse>
          </material>
        </visual>
        <self_collide>0</self_collide>
        <inertial>
          <pose>0 0 0 0 -0 0</pose>
          <inertia>
            <ixx>1</ixx>
            <ixy>0</ixy>
            <ixz>0</ixz>
            <iyy>1</iyy>
            <iyz>0</iyz>
            <izz>1</izz>
          </inertia>
          <mass>1</mass>
        </inertial>
        <enable_wind>0</enable_wind>
        <kinematic>0</kinematic>
      </link>
      <pose>0 -3 0 0 -0 0</pose>
    </model>
    <state world_name='default'>
      <sim_time>1791 221000000</sim_time>
      <real_time>1800 500849675</real_time>
      <wall_time>1767446756 890127174</wall_time>
      <iterations>1791221</iterations>
      <model name='Construction Cone'>
        <pose>6 7 -2e-06 0 1e-06 0</pose>
        <scale>1 1 1</scale>
        <link name='link'>
          <pose>6 7 -2e-06 0 1e-06 0</pose>
          <velocity>0 0 0 0 -0 0</velocity>
          <acceleration>0 0 -9.8 0 -0 0</acceleration>
          <wrench>0 0 -9.8 0 -0 0</wrench>
        </link>
      </model>
      <model name='Construction Cone_0'>
        <pose>0 -3 -2e-06 0 -0 0</pose>
        <scale>1 1 1</scale>
        <link name='link'>
          <pose>0 -3 -2e-06 0 -0 0</pose>
          <velocity>0 0 0 0 -0 0</velocity>
          <acceleration>0 0 -9.8 0 -0 0</acceleration>
          <wrench>0 0 -9.8 0 -0 0</wrench>
        </link>
      </model>
      <model name='cone_2_clone'>
        <pose>6.99792 -1.58704 -8e-06 0 -1e-06 0.001134</pose>
        <scale>1 1 1</scale>
        <link name='link'>
          <pose>6.99792 -1.58704 -8e-06 0 -1e-06 0.001134</pose>
          <velocity>0 0 0 0 -0 0</velocity>
          <acceleration>0 0 -9.8 0 -0 0</acceleration>
          <wrench>0 0 -9.8 0 -0 0</wrench>
        </link>
      </model>
      <model name='cone_2_clone_clone'>
        <pose>-3 6 -2e-06 0 1e-06 0</pose>
        <scale>1 1 1</scale>
        <link name='link'>
          <pose>-3 6 -2e-06 0 1e-06 0</pose>
          <velocity>0 0 0 0 -0 0</velocity>
          <acceleration>0 0 -9.8 0 -0 0</acceleration>
          <wrench>0 0 -9.8 0 -0 0</wrench>
        </link>
      </model>
      <model name='ground_plane'>
        <pose>0 0 0 0 -0 0</pose>
        <scale>1 1 1</scale>
        <link name='link'>
          <pose>0 0 0 0 -0 0</pose>
          <velocity>0 0 0 0 -0 0</velocity>
          <acceleration>0 0 0 0 -0 0</acceleration>
          <wrench>0 0 0 0 -0 0</wrench>
        </link>
      </model>
      <model name='kratos'>
        <pose>4.53154 0.001553 0.600735 -0.000355 0.000187 -0.480183</pose>
        <scale>1 1 1</scale>
        <link name='base_link'>
          <pose>4.53154 0.001553 0.600735 -0.000355 0.000187 -0.480183</pose>
          <velocity>5.9e-05 0.002374 -0.007711 -0.002446 0.001855 -0.008288</velocity>
          <acceleration>-0.001626 -0.001515 -0.000115 0.008001 -0.008694 9.3e-05</acceleration>
          <wrench>-0.032528 -0.030304 -0.00231 0 -0 0</wrench>
        </link>
        <link name='left_wheel_front'>
          <pose>5.11711 0.260117 0.100483 -3.14054 1.22716 2.6624</pose>
          <velocity>0.001273 -0.003706 -0.009431 0.024349 0.053303 -0.008309</velocity>
          <acceleration>0.002674 0.002515 0.00706 0.010268 -0.005348 -2.2e-05</acceleration>
          <wrench>0.005348 0.00503 0.014119 0 -0 0</wrench>
        </link>
        <link name='left_wheel_middle'>
          <pose>4.76234 0.444894 0.100558 -0.000631 0.973723 -0.480704</pose>
          <velocity>0.002805 -0.00077 -0.009229 -0.002453 0.001858 -0.008292</velocity>
          <acceleration>0.002705 0.002432 0.005423 0.007947 -0.008733 4.4e-05</acceleration>
          <wrench>0.005411 0.004863 0.010847 0 -0 0</wrench>
        </link>
        <link name='left_wheel_rear'>
          <pose>4.40758 0.62967 0.100632 -3.14117 0.551868 2.66163</pose>
          <velocity>0.004332 0.002193 -0.009056 -0.04108 -0.073577 -0.008263</velocity>
          <acceleration>0.002719 0.002451 0.003634 -0.03883 -0.101665 0.000216</acceleration>
          <wrench>0.005438 0.004902 0.007268 0 -0 0</wrench>
        </link>
        <link name='right_wheel_front'>
          <pose>4.65517 -0.626793 0.100837 -0.000357 -0.004292 -0.480181</pose>
          <velocity>-0.006086 0.000132 -0.006436 -0.038713 -0.067191 -0.008266</velocity>
          <acceleration>0.002681 0.002634 -0.003813 0.057581 0.079051 0.000116</acceleration>
          <wrench>0.005362 0.005267 -0.007625 0 -0 0</wrench>
        </link>
        <link name='right_wheel_middle'>
          <pose>4.3004 -0.442017 0.100912 -0.000631 0.973991 -0.480704</pose>
          <velocity>-0.004551 0.003071 -0.006195 -0.033462 -0.0577 -0.008269</velocity>
          <acceleration>0.002721 0.00259 -0.005744 -1.66115 0.82459 3.13584</acceleration>
          <wrench>0.005442 0.00518 -0.011488 0 -0 0</wrench>
        </link>
        <link name='right_wheel_rear'>
          <pose>3.94564 -0.25724 0.100987 -3.13446 -1.52109 2.65428</pose>
          <velocity>-0.003015 0.00601 -0.005983 0.060157 0.122054 -0.008338</velocity>
          <acceleration>0.002763 0.002531 -0.007294 0.010929 -0.005692 -0.000227</acceleration>
          <wrench>0.005526 0.005062 -0.014587 0 -0 0</wrench>
        </link>
      </model>
      <light name='sun'>
        <pose>0 0 10 0 -0 0</pose>
      </light>
    </state>
    <gui fullscreen='0'>
      <camera name='user_camera'>
        <pose>2.99844 -10.1766 12.0768 0 0.795643 1.54419</pose>
        <view_controller>orbit</view_controller>
        <projection_type>perspective</projection_type>
      </camera>
    </gui>
  </world>
</sdf>
